{
 "cells": [
  {
   "cell_type": "markdown",
   "id": "6575ee71",
   "metadata": {},
   "source": [
    "# Week4 Assignment 1\n",
    "\n",
    "Modify a class `Deque` in `ArrayDeque.py`, supporting the following ADT:\n",
    "\n",
    "| Mehod | Function |\n",
    "| ---: | :--- |\n",
    "| `D.add_first(e)` | Add element e at the front of the deque **D**. |\n",
    "| `D.add_last(e)` | Add element e at the end of deque **D**. |\n",
    "| `e = D.delete_first()` | Removes and return element e at the first of deque **D**. |\n",
    "| `e = D.delete_last()` | Removes and return element e at the end of deque **D**. |\n",
    "| `e = D.first()` | Return element e at the first of deque **D**. |\n",
    "| `e = D.last()` | Return element e at the end of deque **D**. |\n",
    "| `D.is_empty()` | Return True if deque **D** does not contain any elements. |\n",
    "| `len(D)` | Return the number of elements in Deque **D**; in Python, we implement this with the special method `__len__`. |\n",
    "\n",
    "* All the operations in the ADT should be O(1) time complexity in amortized analysis. \n",
    "* DO NOT USE `append()`, `extend()`, `pop()`, methods in the `list` module.\n",
    "* Manually manage all the data placements. **Use only `self._data[index]` to assign or retrieve the data from the list**.\n",
    "* Use doubling strategy for resizing the buffer (=`_data`).\n",
    "* You need to resize the buffer when the buffer is full, or the length of Deque is <1/2 of the buffer size"
   ]
  },
  {
   "cell_type": "code",
   "execution_count": 1,
   "id": "eb221b29",
   "metadata": {},
   "outputs": [],
   "source": [
    "from ArrayDeque import Deque, EmptyException"
   ]
  },
  {
   "cell_type": "code",
   "execution_count": null,
   "id": "2ae9cd93",
   "metadata": {},
   "outputs": [],
   "source": [
    "# Test cases\n",
    "\n",
    "d = Deque()\n",
    "\n",
    "for i in range(9):\n",
    "    d.add_first(i)\n",
    "    d.add_last(i+20)\n",
    "    d.add_first(i+10)\n",
    "    \n",
    "for i in range(9):\n",
    "    print(d.delete_last())\n",
    "\n",
    "print(d.first())\n",
    "print(d.last())\n",
    "\n",
    "for i in range(9):\n",
    "    print(d.delete_first())\n",
    "    \n",
    "    \n",
    "for i in range(9):\n",
    "    print(d.delete_last())"
   ]
  },
  {
   "cell_type": "code",
   "execution_count": null,
   "id": "126664ec",
   "metadata": {},
   "outputs": [],
   "source": [
    "d.delete_first() # should raise an exception"
   ]
  },
  {
   "cell_type": "code",
   "execution_count": null,
   "id": "bdcfc8e9",
   "metadata": {},
   "outputs": [],
   "source": [
    "d.last() # should raise an exception"
   ]
  },
  {
   "cell_type": "code",
   "execution_count": null,
   "id": "e5ec0922",
   "metadata": {},
   "outputs": [],
   "source": [
    "# Add your own test cases"
   ]
  },
  {
   "cell_type": "code",
   "execution_count": 2,
   "id": "4f49fc36",
   "metadata": {},
   "outputs": [
    {
     "name": "stdout",
     "output_type": "stream",
     "text": [
      "DEQUE(2: [None, None] / 0, 0 / None, None / 2, 1]\n",
      "DEQUE(2: ['f1', None] / 1, 0 / None, f1 / 2, 0]\n",
      "DEQUE(4: ['f2', 'f1', None, None] / 3, 1 / None, f1 / 4, 1]\n",
      "DEQUE(4: ['f2', 'f1', None, 'f3'] / 2, 1 / None, f1 / 4, 0]\n",
      "DEQUE(8: [None, 'f3', 'f2', 'f1', 'r1', None, None, None] / 0, 4 / None, r1 / 8, 5]\n",
      "DEQUE(8: [None, 'f3', 'f2', 'f1', 'r1', 'r2', None, None] / 0, 5 / None, r2 / 8, 6]\n",
      "DEQUE(8: [None, 'f3', 'f2', 'f1', 'r1', 'r2', 'r3', None] / 0, 6 / None, r3 / 8, 7]\n",
      "DEQUE(8: [None, 'f3', 'f2', 'f1', 'r1', 'r2', 'r3', 'r4'] / 0, 7 / None, r4 / 8, 8]\n",
      "f3\n",
      "DEQUE(8: [None, None, 'f2', 'f1', 'r1', 'r2', 'r3', 'r4'] / 1, 7 / None, r4 / 8, 7]\n",
      "f2\n",
      "DEQUE(8: [None, None, None, 'f1', 'r1', 'r2', 'r3', 'r4'] / 2, 7 / None, r4 / 8, 6]\n",
      "f1\n",
      "DEQUE(8: [None, None, None, None, 'r1', 'r2', 'r3', 'r4'] / 3, 7 / None, r4 / 8, 5]\n",
      "r1\n",
      "DEQUE(8: [None, None, None, None, None, 'r2', 'r3', 'r4'] / 4, 7 / None, r4 / 8, 4]\n"
     ]
    },
    {
     "name": "stderr",
     "output_type": "stream",
     "text": [
      "ERROR:root:\n",
      "UnicodeDecodeError while processing traceback.\n",
      "\n",
      "ERROR:root:\n",
      "UnicodeDecodeError while processing traceback.\n",
      "\n",
      "ERROR:root:\n",
      "UnicodeDecodeError while processing traceback.\n",
      "\n",
      "--- Logging error ---\n",
      "--- Logging error ---\n",
      "--- Logging error ---\n",
      "--- Logging error ---\n",
      "--- Logging error ---\n",
      "Error in sys.excepthook:\n",
      "Traceback (most recent call last):\n",
      "  File \"C:\\Users\\point\\anaconda3\\lib\\linecache.py\", line 46, in getlines\n",
      "    return updatecache(filename, module_globals)\n",
      "  File \"C:\\Users\\point\\anaconda3\\lib\\linecache.py\", line 137, in updatecache\n",
      "    lines = fp.readlines()\n",
      "  File \"C:\\Users\\point\\anaconda3\\lib\\codecs.py\", line 322, in decode\n",
      "    (result, consumed) = self._buffer_decode(data, self.errors, final)\n",
      "UnicodeDecodeError: 'utf-8' codec can't decode byte 0xb0 in position 2726: invalid start byte\n",
      "\n",
      "Original exception was:\n",
      "Traceback (most recent call last):\n",
      "  File \"C:\\Users\\point\\anaconda3\\lib\\site-packages\\IPython\\core\\interactiveshell.py\", line 3444, in run_code\n",
      "    exec(code_obj, self.user_global_ns, self.user_ns)\n",
      "  File \"C:\\Users\\point\\AppData\\Local\\Temp/ipykernel_20060/1190720157.py\", line 30, in <module>\n",
      "  File \"c:\\Users\\point\\python\\CSE203\\week4\\ArrayDeque.py\", line 87, in delete_last\n",
      "TypeError: del_resize() missing 1 required positional argument: 'cap'\n",
      "\n",
      "During handling of the above exception, another exception occurred:\n",
      "\n",
      "Traceback (most recent call last):\n",
      "  File \"C:\\Users\\point\\anaconda3\\lib\\site-packages\\IPython\\core\\interactiveshell.py\", line 2064, in showtraceback\n",
      "    stb = value._render_traceback_()\n",
      "AttributeError: 'TypeError' object has no attribute '_render_traceback_'\n",
      "\n",
      "During handling of the above exception, another exception occurred:\n",
      "\n",
      "Traceback (most recent call last):\n",
      "  File \"C:\\Users\\point\\anaconda3\\lib\\site-packages\\IPython\\core\\interactiveshell.py\", line 3364, in run_ast_nodes\n",
      "    if (await self.run_code(code, result,  async_=asy)):\n",
      "  File \"C:\\Users\\point\\anaconda3\\lib\\site-packages\\IPython\\core\\interactiveshell.py\", line 3461, in run_code\n",
      "    self.showtraceback(running_compiled_code=True)\n",
      "  File \"C:\\Users\\point\\anaconda3\\lib\\site-packages\\IPython\\core\\interactiveshell.py\", line 2066, in showtraceback\n",
      "    stb = self.InteractiveTB.structured_traceback(etype,\n",
      "  File \"C:\\Users\\point\\anaconda3\\lib\\site-packages\\IPython\\core\\ultratb.py\", line 1367, in structured_traceback\n",
      "    return FormattedTB.structured_traceback(\n",
      "  File \"C:\\Users\\point\\anaconda3\\lib\\site-packages\\IPython\\core\\ultratb.py\", line 1267, in structured_traceback\n",
      "    return VerboseTB.structured_traceback(\n",
      "  File \"C:\\Users\\point\\anaconda3\\lib\\site-packages\\IPython\\core\\ultratb.py\", line 1124, in structured_traceback\n",
      "    formatted_exception = self.format_exception_as_a_whole(etype, evalue, etb, number_of_lines_of_context,\n",
      "  File \"C:\\Users\\point\\anaconda3\\lib\\site-packages\\IPython\\core\\ultratb.py\", line 1082, in format_exception_as_a_whole\n",
      "    last_unique, recursion_repeat = find_recursion(orig_etype, evalue, records)\n",
      "  File \"C:\\Users\\point\\anaconda3\\lib\\site-packages\\IPython\\core\\ultratb.py\", line 382, in find_recursion\n",
      "    return len(records), 0\n",
      "TypeError: object of type 'NoneType' has no len()\n",
      "\n",
      "During handling of the above exception, another exception occurred:\n",
      "\n",
      "Traceback (most recent call last):\n",
      "  File \"C:\\Users\\point\\anaconda3\\lib\\site-packages\\IPython\\core\\interactiveshell.py\", line 2064, in showtraceback\n",
      "    stb = value._render_traceback_()\n",
      "AttributeError: 'TypeError' object has no attribute '_render_traceback_'\n",
      "\n",
      "During handling of the above exception, another exception occurred:\n",
      "\n",
      "Traceback (most recent call last):\n",
      "  File \"C:\\Users\\point\\anaconda3\\lib\\site-packages\\IPython\\core\\interactiveshell.py\", line 2947, in _run_cell\n",
      "    return runner(coro)\n",
      "  File \"C:\\Users\\point\\anaconda3\\lib\\site-packages\\IPython\\core\\async_helpers.py\", line 68, in _pseudo_sync_runner\n",
      "    coro.send(None)\n",
      "  File \"C:\\Users\\point\\anaconda3\\lib\\site-packages\\IPython\\core\\interactiveshell.py\", line 3172, in run_cell_async\n",
      "    has_raised = await self.run_ast_nodes(code_ast.body, cell_name,\n",
      "  File \"C:\\Users\\point\\anaconda3\\lib\\site-packages\\IPython\\core\\interactiveshell.py\", line 3383, in run_ast_nodes\n",
      "    self.showtraceback()\n",
      "  File \"C:\\Users\\point\\anaconda3\\lib\\site-packages\\IPython\\core\\interactiveshell.py\", line 2066, in showtraceback\n",
      "    stb = self.InteractiveTB.structured_traceback(etype,\n",
      "  File \"C:\\Users\\point\\anaconda3\\lib\\site-packages\\IPython\\core\\ultratb.py\", line 1367, in structured_traceback\n",
      "    return FormattedTB.structured_traceback(\n",
      "  File \"C:\\Users\\point\\anaconda3\\lib\\site-packages\\IPython\\core\\ultratb.py\", line 1267, in structured_traceback\n",
      "    return VerboseTB.structured_traceback(\n",
      "  File \"C:\\Users\\point\\anaconda3\\lib\\site-packages\\IPython\\core\\ultratb.py\", line 1142, in structured_traceback\n",
      "    formatted_exceptions += self.format_exception_as_a_whole(etype, evalue, etb, lines_of_context,\n",
      "  File \"C:\\Users\\point\\anaconda3\\lib\\site-packages\\IPython\\core\\ultratb.py\", line 1082, in format_exception_as_a_whole\n",
      "    last_unique, recursion_repeat = find_recursion(orig_etype, evalue, records)\n",
      "  File \"C:\\Users\\point\\anaconda3\\lib\\site-packages\\IPython\\core\\ultratb.py\", line 382, in find_recursion\n",
      "    return len(records), 0\n",
      "TypeError: object of type 'NoneType' has no len()\n",
      "\n",
      "During handling of the above exception, another exception occurred:\n",
      "\n",
      "Traceback (most recent call last):\n",
      "  File \"C:\\Users\\point\\anaconda3\\lib\\site-packages\\IPython\\core\\interactiveshell.py\", line 2064, in showtraceback\n",
      "    stb = value._render_traceback_()\n",
      "AttributeError: 'TypeError' object has no attribute '_render_traceback_'\n",
      "\n",
      "During handling of the above exception, another exception occurred:\n",
      "\n",
      "Traceback (most recent call last):\n",
      "  File \"C:\\Users\\point\\anaconda3\\lib\\site-packages\\ipykernel\\kernelbase.py\", line 353, in dispatch_shell\n",
      "    await result\n",
      "  File \"C:\\Users\\point\\anaconda3\\lib\\site-packages\\ipykernel\\kernelbase.py\", line 648, in execute_request\n",
      "    reply_content = await reply_content\n",
      "  File \"C:\\Users\\point\\anaconda3\\lib\\site-packages\\ipykernel\\ipkernel.py\", line 353, in do_execute\n",
      "    res = shell.run_cell(code, store_history=store_history, silent=silent)\n",
      "  File \"C:\\Users\\point\\anaconda3\\lib\\site-packages\\ipykernel\\zmqshell.py\", line 533, in run_cell\n",
      "    return super(ZMQInteractiveShell, self).run_cell(*args, **kwargs)\n",
      "  File \"C:\\Users\\point\\anaconda3\\lib\\site-packages\\IPython\\core\\interactiveshell.py\", line 2901, in run_cell\n",
      "    result = self._run_cell(\n",
      "  File \"C:\\Users\\point\\anaconda3\\lib\\site-packages\\IPython\\core\\interactiveshell.py\", line 2952, in _run_cell\n",
      "    self.showtraceback(running_compiled_code=True)\n",
      "  File \"C:\\Users\\point\\anaconda3\\lib\\site-packages\\IPython\\core\\interactiveshell.py\", line 2066, in showtraceback\n",
      "    stb = self.InteractiveTB.structured_traceback(etype,\n",
      "  File \"C:\\Users\\point\\anaconda3\\lib\\site-packages\\IPython\\core\\ultratb.py\", line 1367, in structured_traceback\n",
      "    return FormattedTB.structured_traceback(\n",
      "  File \"C:\\Users\\point\\anaconda3\\lib\\site-packages\\IPython\\core\\ultratb.py\", line 1267, in structured_traceback\n",
      "    return VerboseTB.structured_traceback(\n",
      "  File \"C:\\Users\\point\\anaconda3\\lib\\site-packages\\IPython\\core\\ultratb.py\", line 1142, in structured_traceback\n",
      "    formatted_exceptions += self.format_exception_as_a_whole(etype, evalue, etb, lines_of_context,\n",
      "  File \"C:\\Users\\point\\anaconda3\\lib\\site-packages\\IPython\\core\\ultratb.py\", line 1082, in format_exception_as_a_whole\n",
      "    last_unique, recursion_repeat = find_recursion(orig_etype, evalue, records)\n",
      "  File \"C:\\Users\\point\\anaconda3\\lib\\site-packages\\IPython\\core\\ultratb.py\", line 382, in find_recursion\n",
      "    return len(records), 0\n",
      "TypeError: object of type 'NoneType' has no len()\n",
      "\n",
      "During handling of the above exception, another exception occurred:\n",
      "\n",
      "Traceback (most recent call last):\n",
      "  File \"C:\\Users\\point\\anaconda3\\lib\\logging\\__init__.py\", line 1083, in emit\n",
      "    msg = self.format(record)\n",
      "  File \"C:\\Users\\point\\anaconda3\\lib\\logging\\__init__.py\", line 927, in format\n",
      "    return fmt.format(record)\n",
      "  File \"C:\\Users\\point\\anaconda3\\lib\\site-packages\\traitlets\\config\\application.py\", line 117, in format\n",
      "    return super(LevelFormatter, self).format(record)\n",
      "  File \"C:\\Users\\point\\anaconda3\\lib\\logging\\__init__.py\", line 671, in format\n",
      "    record.exc_text = self.formatException(record.exc_info)\n",
      "  File \"C:\\Users\\point\\anaconda3\\lib\\logging\\__init__.py\", line 621, in formatException\n",
      "    traceback.print_exception(ei[0], ei[1], tb, None, sio)\n",
      "  File \"C:\\Users\\point\\anaconda3\\lib\\traceback.py\", line 103, in print_exception\n",
      "    for line in TracebackException(\n",
      "  File \"C:\\Users\\point\\anaconda3\\lib\\traceback.py\", line 533, in __init__\n",
      "    self._load_lines()\n",
      "  File \"C:\\Users\\point\\anaconda3\\lib\\traceback.py\", line 545, in _load_lines\n",
      "    self.__context__._load_lines()\n",
      "  File \"C:\\Users\\point\\anaconda3\\lib\\traceback.py\", line 545, in _load_lines\n",
      "    self.__context__._load_lines()\n",
      "  File \"C:\\Users\\point\\anaconda3\\lib\\traceback.py\", line 545, in _load_lines\n",
      "    self.__context__._load_lines()\n",
      "  [Previous line repeated 3 more times]\n",
      "  File \"C:\\Users\\point\\anaconda3\\lib\\traceback.py\", line 543, in _load_lines\n",
      "    frame.line\n",
      "  File \"C:\\Users\\point\\anaconda3\\lib\\traceback.py\", line 288, in line\n",
      "    self._line = linecache.getline(self.filename, self.lineno).strip()\n",
      "  File \"C:\\Users\\point\\anaconda3\\lib\\linecache.py\", line 30, in getline\n",
      "    lines = getlines(filename, module_globals)\n",
      "  File \"C:\\Users\\point\\anaconda3\\lib\\linecache.py\", line 46, in getlines\n",
      "    return updatecache(filename, module_globals)\n",
      "  File \"C:\\Users\\point\\anaconda3\\lib\\linecache.py\", line 137, in updatecache\n",
      "    lines = fp.readlines()\n",
      "  File \"C:\\Users\\point\\anaconda3\\lib\\codecs.py\", line 322, in decode\n",
      "    (result, consumed) = self._buffer_decode(data, self.errors, final)\n",
      "UnicodeDecodeError: 'utf-8' codec can't decode byte 0xb0 in position 2726: invalid start byte\n",
      "\n",
      "During handling of the above exception, another exception occurred:\n",
      "\n",
      "Traceback (most recent call last):\n",
      "  File \"C:\\Users\\point\\anaconda3\\lib\\site-packages\\ipykernel\\kernelbase.py\", line 457, in dispatch_queue\n",
      "    await self.process_one()\n",
      "  File \"C:\\Users\\point\\anaconda3\\lib\\site-packages\\ipykernel\\kernelbase.py\", line 446, in process_one\n",
      "    await dispatch(*args)\n",
      "  File \"C:\\Users\\point\\anaconda3\\lib\\site-packages\\ipykernel\\kernelbase.py\", line 355, in dispatch_shell\n",
      "    self.log.error(\"Exception in message handler:\", exc_info=True)\n",
      "  File \"C:\\Users\\point\\anaconda3\\lib\\logging\\__init__.py\", line 1475, in error\n",
      "    self._log(ERROR, msg, args, **kwargs)\n",
      "  File \"C:\\Users\\point\\anaconda3\\lib\\logging\\__init__.py\", line 1589, in _log\n",
      "    self.handle(record)\n",
      "  File \"C:\\Users\\point\\anaconda3\\lib\\logging\\__init__.py\", line 1599, in handle\n",
      "    self.callHandlers(record)\n",
      "  File \"C:\\Users\\point\\anaconda3\\lib\\logging\\__init__.py\", line 1661, in callHandlers\n",
      "    hdlr.handle(record)\n",
      "  File \"C:\\Users\\point\\anaconda3\\lib\\logging\\__init__.py\", line 952, in handle\n",
      "    self.emit(record)\n",
      "  File \"C:\\Users\\point\\anaconda3\\lib\\logging\\__init__.py\", line 1091, in emit\n",
      "    self.handleError(record)\n",
      "  File \"C:\\Users\\point\\anaconda3\\lib\\logging\\__init__.py\", line 1005, in handleError\n",
      "    traceback.print_exception(t, v, tb, None, sys.stderr)\n",
      "  File \"C:\\Users\\point\\anaconda3\\lib\\traceback.py\", line 103, in print_exception\n",
      "    for line in TracebackException(\n",
      "  File \"C:\\Users\\point\\anaconda3\\lib\\traceback.py\", line 533, in __init__\n",
      "    self._load_lines()\n",
      "  File \"C:\\Users\\point\\anaconda3\\lib\\traceback.py\", line 545, in _load_lines\n",
      "    self.__context__._load_lines()\n",
      "  File \"C:\\Users\\point\\anaconda3\\lib\\traceback.py\", line 545, in _load_lines\n",
      "    self.__context__._load_lines()\n",
      "  File \"C:\\Users\\point\\anaconda3\\lib\\traceback.py\", line 545, in _load_lines\n",
      "    self.__context__._load_lines()\n",
      "  [Previous line repeated 4 more times]\n",
      "  File \"C:\\Users\\point\\anaconda3\\lib\\traceback.py\", line 543, in _load_lines\n",
      "    frame.line\n",
      "  File \"C:\\Users\\point\\anaconda3\\lib\\traceback.py\", line 288, in line\n",
      "    self._line = linecache.getline(self.filename, self.lineno).strip()\n",
      "  File \"C:\\Users\\point\\anaconda3\\lib\\linecache.py\", line 30, in getline\n",
      "    lines = getlines(filename, module_globals)\n",
      "  File \"C:\\Users\\point\\anaconda3\\lib\\linecache.py\", line 46, in getlines\n",
      "    return updatecache(filename, module_globals)\n",
      "  File \"C:\\Users\\point\\anaconda3\\lib\\linecache.py\", line 137, in updatecache\n",
      "    lines = fp.readlines()\n",
      "  File \"C:\\Users\\point\\anaconda3\\lib\\codecs.py\", line 322, in decode\n",
      "    (result, consumed) = self._buffer_decode(data, self.errors, final)\n",
      "UnicodeDecodeError: 'utf-8' codec can't decode byte 0xb0 in position 2726: invalid start byte\n",
      "\n",
      "During handling of the above exception, another exception occurred:\n",
      "\n",
      "Traceback (most recent call last):\n",
      "  File \"C:\\Users\\point\\anaconda3\\lib\\logging\\__init__.py\", line 1083, in emit\n",
      "    msg = self.format(record)\n",
      "  File \"C:\\Users\\point\\anaconda3\\lib\\logging\\__init__.py\", line 927, in format\n",
      "    return fmt.format(record)\n",
      "  File \"C:\\Users\\point\\anaconda3\\lib\\site-packages\\traitlets\\config\\application.py\", line 117, in format\n",
      "    return super(LevelFormatter, self).format(record)\n",
      "  File \"C:\\Users\\point\\anaconda3\\lib\\logging\\__init__.py\", line 671, in format\n",
      "    record.exc_text = self.formatException(record.exc_info)\n",
      "  File \"C:\\Users\\point\\anaconda3\\lib\\logging\\__init__.py\", line 621, in formatException\n",
      "    traceback.print_exception(ei[0], ei[1], tb, None, sio)\n",
      "  File \"C:\\Users\\point\\anaconda3\\lib\\traceback.py\", line 103, in print_exception\n",
      "    for line in TracebackException(\n",
      "  File \"C:\\Users\\point\\anaconda3\\lib\\traceback.py\", line 533, in __init__\n",
      "    self._load_lines()\n",
      "  File \"C:\\Users\\point\\anaconda3\\lib\\traceback.py\", line 545, in _load_lines\n",
      "    self.__context__._load_lines()\n",
      "  File \"C:\\Users\\point\\anaconda3\\lib\\traceback.py\", line 545, in _load_lines\n",
      "    self.__context__._load_lines()\n",
      "  File \"C:\\Users\\point\\anaconda3\\lib\\traceback.py\", line 545, in _load_lines\n",
      "    self.__context__._load_lines()\n",
      "  [Previous line repeated 5 more times]\n",
      "  File \"C:\\Users\\point\\anaconda3\\lib\\traceback.py\", line 543, in _load_lines\n",
      "    frame.line\n",
      "  File \"C:\\Users\\point\\anaconda3\\lib\\traceback.py\", line 288, in line\n",
      "    self._line = linecache.getline(self.filename, self.lineno).strip()\n",
      "  File \"C:\\Users\\point\\anaconda3\\lib\\linecache.py\", line 30, in getline\n",
      "    lines = getlines(filename, module_globals)\n",
      "  File \"C:\\Users\\point\\anaconda3\\lib\\linecache.py\", line 46, in getlines\n",
      "    return updatecache(filename, module_globals)\n",
      "  File \"C:\\Users\\point\\anaconda3\\lib\\linecache.py\", line 137, in updatecache\n",
      "    lines = fp.readlines()\n",
      "  File \"C:\\Users\\point\\anaconda3\\lib\\codecs.py\", line 322, in decode\n",
      "    (result, consumed) = self._buffer_decode(data, self.errors, final)\n",
      "UnicodeDecodeError: 'utf-8' codec can't decode byte 0xb0 in position 2726: invalid start byte\n",
      "\n",
      "During handling of the above exception, another exception occurred:\n",
      "\n",
      "Traceback (most recent call last):\n",
      "  File \"C:\\Users\\point\\anaconda3\\lib\\site-packages\\tornado\\ioloop.py\", line 741, in _run_callback\n",
      "    ret = callback()\n",
      "  File \"C:\\Users\\point\\anaconda3\\lib\\site-packages\\tornado\\ioloop.py\", line 765, in _discard_future_result\n",
      "    future.result()\n",
      "  File \"C:\\Users\\point\\anaconda3\\lib\\site-packages\\ipykernel\\kernelbase.py\", line 459, in dispatch_queue\n",
      "    self.log.exception(\"Error in message handler\")\n",
      "  File \"C:\\Users\\point\\anaconda3\\lib\\logging\\__init__.py\", line 1481, in exception\n",
      "    self.error(msg, *args, exc_info=exc_info, **kwargs)\n",
      "  File \"C:\\Users\\point\\anaconda3\\lib\\logging\\__init__.py\", line 1475, in error\n",
      "    self._log(ERROR, msg, args, **kwargs)\n",
      "  File \"C:\\Users\\point\\anaconda3\\lib\\logging\\__init__.py\", line 1589, in _log\n",
      "    self.handle(record)\n",
      "  File \"C:\\Users\\point\\anaconda3\\lib\\logging\\__init__.py\", line 1599, in handle\n",
      "    self.callHandlers(record)\n",
      "  File \"C:\\Users\\point\\anaconda3\\lib\\logging\\__init__.py\", line 1661, in callHandlers\n",
      "    hdlr.handle(record)\n",
      "  File \"C:\\Users\\point\\anaconda3\\lib\\logging\\__init__.py\", line 952, in handle\n",
      "    self.emit(record)\n",
      "  File \"C:\\Users\\point\\anaconda3\\lib\\logging\\__init__.py\", line 1091, in emit\n",
      "    self.handleError(record)\n",
      "  File \"C:\\Users\\point\\anaconda3\\lib\\logging\\__init__.py\", line 1005, in handleError\n",
      "    traceback.print_exception(t, v, tb, None, sys.stderr)\n",
      "  File \"C:\\Users\\point\\anaconda3\\lib\\traceback.py\", line 103, in print_exception\n",
      "    for line in TracebackException(\n",
      "  File \"C:\\Users\\point\\anaconda3\\lib\\traceback.py\", line 533, in __init__\n",
      "    self._load_lines()\n",
      "  File \"C:\\Users\\point\\anaconda3\\lib\\traceback.py\", line 545, in _load_lines\n",
      "    self.__context__._load_lines()\n",
      "  File \"C:\\Users\\point\\anaconda3\\lib\\traceback.py\", line 545, in _load_lines\n",
      "    self.__context__._load_lines()\n",
      "  File \"C:\\Users\\point\\anaconda3\\lib\\traceback.py\", line 545, in _load_lines\n",
      "    self.__context__._load_lines()\n",
      "  [Previous line repeated 6 more times]\n",
      "  File \"C:\\Users\\point\\anaconda3\\lib\\traceback.py\", line 543, in _load_lines\n",
      "    frame.line\n",
      "  File \"C:\\Users\\point\\anaconda3\\lib\\traceback.py\", line 288, in line\n",
      "    self._line = linecache.getline(self.filename, self.lineno).strip()\n",
      "  File \"C:\\Users\\point\\anaconda3\\lib\\linecache.py\", line 30, in getline\n",
      "    lines = getlines(filename, module_globals)\n",
      "  File \"C:\\Users\\point\\anaconda3\\lib\\linecache.py\", line 46, in getlines\n",
      "    return updatecache(filename, module_globals)\n",
      "  File \"C:\\Users\\point\\anaconda3\\lib\\linecache.py\", line 137, in updatecache\n",
      "    lines = fp.readlines()\n",
      "  File \"C:\\Users\\point\\anaconda3\\lib\\codecs.py\", line 322, in decode\n",
      "    (result, consumed) = self._buffer_decode(data, self.errors, final)\n",
      "UnicodeDecodeError: 'utf-8' codec can't decode byte 0xb0 in position 2726: invalid start byte\n",
      "\n",
      "During handling of the above exception, another exception occurred:\n",
      "\n",
      "Traceback (most recent call last):\n",
      "  File \"C:\\Users\\point\\anaconda3\\lib\\logging\\__init__.py\", line 1083, in emit\n",
      "    msg = self.format(record)\n",
      "  File \"C:\\Users\\point\\anaconda3\\lib\\logging\\__init__.py\", line 927, in format\n",
      "    return fmt.format(record)\n",
      "  File \"C:\\Users\\point\\anaconda3\\lib\\logging\\__init__.py\", line 671, in format\n",
      "    record.exc_text = self.formatException(record.exc_info)\n",
      "  File \"C:\\Users\\point\\anaconda3\\lib\\logging\\__init__.py\", line 621, in formatException\n",
      "    traceback.print_exception(ei[0], ei[1], tb, None, sio)\n",
      "  File \"C:\\Users\\point\\anaconda3\\lib\\traceback.py\", line 103, in print_exception\n",
      "    for line in TracebackException(\n",
      "  File \"C:\\Users\\point\\anaconda3\\lib\\traceback.py\", line 533, in __init__\n",
      "    self._load_lines()\n",
      "  File \"C:\\Users\\point\\anaconda3\\lib\\traceback.py\", line 545, in _load_lines\n",
      "    self.__context__._load_lines()\n",
      "  File \"C:\\Users\\point\\anaconda3\\lib\\traceback.py\", line 545, in _load_lines\n",
      "    self.__context__._load_lines()\n",
      "  File \"C:\\Users\\point\\anaconda3\\lib\\traceback.py\", line 545, in _load_lines\n",
      "    self.__context__._load_lines()\n",
      "  [Previous line repeated 7 more times]\n",
      "  File \"C:\\Users\\point\\anaconda3\\lib\\traceback.py\", line 543, in _load_lines\n",
      "    frame.line\n",
      "  File \"C:\\Users\\point\\anaconda3\\lib\\traceback.py\", line 288, in line\n",
      "    self._line = linecache.getline(self.filename, self.lineno).strip()\n",
      "  File \"C:\\Users\\point\\anaconda3\\lib\\linecache.py\", line 30, in getline\n",
      "    lines = getlines(filename, module_globals)\n",
      "  File \"C:\\Users\\point\\anaconda3\\lib\\linecache.py\", line 46, in getlines\n",
      "    return updatecache(filename, module_globals)\n",
      "  File \"C:\\Users\\point\\anaconda3\\lib\\linecache.py\", line 137, in updatecache\n",
      "    lines = fp.readlines()\n",
      "  File \"C:\\Users\\point\\anaconda3\\lib\\codecs.py\", line 322, in decode\n",
      "    (result, consumed) = self._buffer_decode(data, self.errors, final)\n",
      "UnicodeDecodeError: 'utf-8' codec can't decode byte 0xb0 in position 2726: invalid start byte\n",
      "\n",
      "During handling of the above exception, another exception occurred:\n",
      "\n",
      "Traceback (most recent call last):\n",
      "  File \"C:\\Users\\point\\anaconda3\\lib\\asyncio\\events.py\", line 80, in _run\n",
      "    self._context.run(self._callback, *self._args)\n",
      "  File \"C:\\Users\\point\\anaconda3\\lib\\site-packages\\tornado\\ioloop.py\", line 688, in <lambda>\n",
      "    lambda f: self._run_callback(functools.partial(callback, future))\n",
      "  File \"C:\\Users\\point\\anaconda3\\lib\\site-packages\\tornado\\ioloop.py\", line 761, in _run_callback\n",
      "    app_log.error(\"Exception in callback %r\", callback, exc_info=True)\n",
      "  File \"C:\\Users\\point\\anaconda3\\lib\\logging\\__init__.py\", line 1475, in error\n",
      "    self._log(ERROR, msg, args, **kwargs)\n",
      "  File \"C:\\Users\\point\\anaconda3\\lib\\logging\\__init__.py\", line 1589, in _log\n",
      "    self.handle(record)\n",
      "  File \"C:\\Users\\point\\anaconda3\\lib\\logging\\__init__.py\", line 1599, in handle\n",
      "    self.callHandlers(record)\n",
      "  File \"C:\\Users\\point\\anaconda3\\lib\\logging\\__init__.py\", line 1661, in callHandlers\n",
      "    hdlr.handle(record)\n",
      "  File \"C:\\Users\\point\\anaconda3\\lib\\logging\\__init__.py\", line 952, in handle\n",
      "    self.emit(record)\n",
      "  File \"C:\\Users\\point\\anaconda3\\lib\\logging\\__init__.py\", line 1091, in emit\n",
      "    self.handleError(record)\n",
      "  File \"C:\\Users\\point\\anaconda3\\lib\\logging\\__init__.py\", line 1005, in handleError\n",
      "    traceback.print_exception(t, v, tb, None, sys.stderr)\n",
      "  File \"C:\\Users\\point\\anaconda3\\lib\\traceback.py\", line 103, in print_exception\n",
      "    for line in TracebackException(\n",
      "  File \"C:\\Users\\point\\anaconda3\\lib\\traceback.py\", line 533, in __init__\n",
      "    self._load_lines()\n",
      "  File \"C:\\Users\\point\\anaconda3\\lib\\traceback.py\", line 545, in _load_lines\n",
      "    self.__context__._load_lines()\n",
      "  File \"C:\\Users\\point\\anaconda3\\lib\\traceback.py\", line 545, in _load_lines\n",
      "    self.__context__._load_lines()\n",
      "  File \"C:\\Users\\point\\anaconda3\\lib\\traceback.py\", line 545, in _load_lines\n",
      "    self.__context__._load_lines()\n",
      "  [Previous line repeated 8 more times]\n",
      "  File \"C:\\Users\\point\\anaconda3\\lib\\traceback.py\", line 543, in _load_lines\n",
      "    frame.line\n",
      "  File \"C:\\Users\\point\\anaconda3\\lib\\traceback.py\", line 288, in line\n",
      "    self._line = linecache.getline(self.filename, self.lineno).strip()\n",
      "  File \"C:\\Users\\point\\anaconda3\\lib\\linecache.py\", line 30, in getline\n",
      "    lines = getlines(filename, module_globals)\n",
      "  File \"C:\\Users\\point\\anaconda3\\lib\\linecache.py\", line 46, in getlines\n",
      "    return updatecache(filename, module_globals)\n",
      "  File \"C:\\Users\\point\\anaconda3\\lib\\linecache.py\", line 137, in updatecache\n",
      "    lines = fp.readlines()\n",
      "  File \"C:\\Users\\point\\anaconda3\\lib\\codecs.py\", line 322, in decode\n",
      "    (result, consumed) = self._buffer_decode(data, self.errors, final)\n",
      "UnicodeDecodeError: 'utf-8' codec can't decode byte 0xb0 in position 2726: invalid start byte\n",
      "\n",
      "During handling of the above exception, another exception occurred:\n",
      "\n",
      "Traceback (most recent call last):\n",
      "  File \"C:\\Users\\point\\anaconda3\\lib\\logging\\__init__.py\", line 1083, in emit\n",
      "    msg = self.format(record)\n",
      "  File \"C:\\Users\\point\\anaconda3\\lib\\logging\\__init__.py\", line 927, in format\n",
      "    return fmt.format(record)\n",
      "  File \"C:\\Users\\point\\anaconda3\\lib\\logging\\__init__.py\", line 671, in format\n",
      "    record.exc_text = self.formatException(record.exc_info)\n",
      "  File \"C:\\Users\\point\\anaconda3\\lib\\logging\\__init__.py\", line 621, in formatException\n",
      "    traceback.print_exception(ei[0], ei[1], tb, None, sio)\n",
      "  File \"C:\\Users\\point\\anaconda3\\lib\\traceback.py\", line 103, in print_exception\n",
      "    for line in TracebackException(\n",
      "  File \"C:\\Users\\point\\anaconda3\\lib\\traceback.py\", line 533, in __init__\n",
      "    self._load_lines()\n",
      "  File \"C:\\Users\\point\\anaconda3\\lib\\traceback.py\", line 545, in _load_lines\n",
      "    self.__context__._load_lines()\n",
      "  File \"C:\\Users\\point\\anaconda3\\lib\\traceback.py\", line 545, in _load_lines\n",
      "    self.__context__._load_lines()\n",
      "  File \"C:\\Users\\point\\anaconda3\\lib\\traceback.py\", line 545, in _load_lines\n",
      "    self.__context__._load_lines()\n",
      "  [Previous line repeated 9 more times]\n",
      "  File \"C:\\Users\\point\\anaconda3\\lib\\traceback.py\", line 543, in _load_lines\n",
      "    frame.line\n",
      "  File \"C:\\Users\\point\\anaconda3\\lib\\traceback.py\", line 288, in line\n",
      "    self._line = linecache.getline(self.filename, self.lineno).strip()\n",
      "  File \"C:\\Users\\point\\anaconda3\\lib\\linecache.py\", line 30, in getline\n",
      "    lines = getlines(filename, module_globals)\n",
      "  File \"C:\\Users\\point\\anaconda3\\lib\\linecache.py\", line 46, in getlines\n",
      "    return updatecache(filename, module_globals)\n",
      "  File \"C:\\Users\\point\\anaconda3\\lib\\linecache.py\", line 137, in updatecache\n",
      "    lines = fp.readlines()\n",
      "  File \"C:\\Users\\point\\anaconda3\\lib\\codecs.py\", line 322, in decode\n",
      "    (result, consumed) = self._buffer_decode(data, self.errors, final)\n",
      "UnicodeDecodeError: 'utf-8' codec can't decode byte 0xb0 in position 2726: invalid start byte\n",
      "\n",
      "During handling of the above exception, another exception occurred:\n",
      "\n",
      "Traceback (most recent call last):\n",
      "  File \"C:\\Users\\point\\anaconda3\\lib\\asyncio\\base_events.py\", line 1764, in call_exception_handler\n",
      "    self.default_exception_handler(context)\n",
      "  File \"C:\\Users\\point\\anaconda3\\lib\\asyncio\\base_events.py\", line 1738, in default_exception_handler\n",
      "    logger.error('\\n'.join(log_lines), exc_info=exc_info)\n",
      "  File \"C:\\Users\\point\\anaconda3\\lib\\logging\\__init__.py\", line 1475, in error\n",
      "    self._log(ERROR, msg, args, **kwargs)\n",
      "  File \"C:\\Users\\point\\anaconda3\\lib\\logging\\__init__.py\", line 1589, in _log\n",
      "    self.handle(record)\n",
      "  File \"C:\\Users\\point\\anaconda3\\lib\\logging\\__init__.py\", line 1599, in handle\n",
      "    self.callHandlers(record)\n",
      "  File \"C:\\Users\\point\\anaconda3\\lib\\logging\\__init__.py\", line 1661, in callHandlers\n",
      "    hdlr.handle(record)\n",
      "  File \"C:\\Users\\point\\anaconda3\\lib\\logging\\__init__.py\", line 952, in handle\n",
      "    self.emit(record)\n",
      "  File \"C:\\Users\\point\\anaconda3\\lib\\logging\\__init__.py\", line 1091, in emit\n",
      "    self.handleError(record)\n",
      "  File \"C:\\Users\\point\\anaconda3\\lib\\logging\\__init__.py\", line 1005, in handleError\n",
      "    traceback.print_exception(t, v, tb, None, sys.stderr)\n",
      "  File \"C:\\Users\\point\\anaconda3\\lib\\traceback.py\", line 103, in print_exception\n",
      "    for line in TracebackException(\n",
      "  File \"C:\\Users\\point\\anaconda3\\lib\\traceback.py\", line 533, in __init__\n",
      "    self._load_lines()\n",
      "  File \"C:\\Users\\point\\anaconda3\\lib\\traceback.py\", line 545, in _load_lines\n",
      "    self.__context__._load_lines()\n",
      "  File \"C:\\Users\\point\\anaconda3\\lib\\traceback.py\", line 545, in _load_lines\n",
      "    self.__context__._load_lines()\n",
      "  File \"C:\\Users\\point\\anaconda3\\lib\\traceback.py\", line 545, in _load_lines\n",
      "    self.__context__._load_lines()\n",
      "  [Previous line repeated 10 more times]\n",
      "  File \"C:\\Users\\point\\anaconda3\\lib\\traceback.py\", line 543, in _load_lines\n",
      "    frame.line\n",
      "  File \"C:\\Users\\point\\anaconda3\\lib\\traceback.py\", line 288, in line\n",
      "    self._line = linecache.getline(self.filename, self.lineno).strip()\n",
      "  File \"C:\\Users\\point\\anaconda3\\lib\\linecache.py\", line 30, in getline\n",
      "    lines = getlines(filename, module_globals)\n",
      "  File \"C:\\Users\\point\\anaconda3\\lib\\linecache.py\", line 46, in getlines\n",
      "    return updatecache(filename, module_globals)\n",
      "  File \"C:\\Users\\point\\anaconda3\\lib\\linecache.py\", line 137, in updatecache\n",
      "    lines = fp.readlines()\n",
      "  File \"C:\\Users\\point\\anaconda3\\lib\\codecs.py\", line 322, in decode\n",
      "    (result, consumed) = self._buffer_decode(data, self.errors, final)\n",
      "UnicodeDecodeError: 'utf-8' codec can't decode byte 0xb0 in position 2726: invalid start byte\n",
      "\n",
      "During handling of the above exception, another exception occurred:\n",
      "\n",
      "Traceback (most recent call last):\n",
      "  File \"C:\\Users\\point\\anaconda3\\lib\\logging\\__init__.py\", line 1083, in emit\n",
      "    msg = self.format(record)\n",
      "  File \"C:\\Users\\point\\anaconda3\\lib\\logging\\__init__.py\", line 927, in format\n",
      "    return fmt.format(record)\n",
      "  File \"C:\\Users\\point\\anaconda3\\lib\\logging\\__init__.py\", line 671, in format\n",
      "    record.exc_text = self.formatException(record.exc_info)\n",
      "  File \"C:\\Users\\point\\anaconda3\\lib\\logging\\__init__.py\", line 621, in formatException\n",
      "    traceback.print_exception(ei[0], ei[1], tb, None, sio)\n",
      "  File \"C:\\Users\\point\\anaconda3\\lib\\traceback.py\", line 103, in print_exception\n",
      "    for line in TracebackException(\n",
      "  File \"C:\\Users\\point\\anaconda3\\lib\\traceback.py\", line 533, in __init__\n",
      "    self._load_lines()\n",
      "  File \"C:\\Users\\point\\anaconda3\\lib\\traceback.py\", line 545, in _load_lines\n",
      "    self.__context__._load_lines()\n",
      "  File \"C:\\Users\\point\\anaconda3\\lib\\traceback.py\", line 545, in _load_lines\n",
      "    self.__context__._load_lines()\n",
      "  File \"C:\\Users\\point\\anaconda3\\lib\\traceback.py\", line 545, in _load_lines\n",
      "    self.__context__._load_lines()\n",
      "  [Previous line repeated 11 more times]\n",
      "  File \"C:\\Users\\point\\anaconda3\\lib\\traceback.py\", line 543, in _load_lines\n",
      "    frame.line\n",
      "  File \"C:\\Users\\point\\anaconda3\\lib\\traceback.py\", line 288, in line\n",
      "    self._line = linecache.getline(self.filename, self.lineno).strip()\n",
      "  File \"C:\\Users\\point\\anaconda3\\lib\\linecache.py\", line 30, in getline\n",
      "    lines = getlines(filename, module_globals)\n",
      "  File \"C:\\Users\\point\\anaconda3\\lib\\linecache.py\", line 46, in getlines\n",
      "    return updatecache(filename, module_globals)\n",
      "  File \"C:\\Users\\point\\anaconda3\\lib\\linecache.py\", line 137, in updatecache\n",
      "    lines = fp.readlines()\n",
      "  File \"C:\\Users\\point\\anaconda3\\lib\\codecs.py\", line 322, in decode\n",
      "    (result, consumed) = self._buffer_decode(data, self.errors, final)\n",
      "UnicodeDecodeError: 'utf-8' codec can't decode byte 0xb0 in position 2726: invalid start byte\n",
      "\n",
      "During handling of the above exception, another exception occurred:\n",
      "\n",
      "Traceback (most recent call last):\n",
      "  File \"C:\\Users\\point\\anaconda3\\lib\\runpy.py\", line 197, in _run_module_as_main\n",
      "    return _run_code(code, main_globals, None,\n",
      "  File \"C:\\Users\\point\\anaconda3\\lib\\runpy.py\", line 87, in _run_code\n",
      "    exec(code, run_globals)\n",
      "  File \"C:\\Users\\point\\anaconda3\\lib\\site-packages\\ipykernel_launcher.py\", line 16, in <module>\n",
      "    app.launch_new_instance()\n",
      "  File \"C:\\Users\\point\\anaconda3\\lib\\site-packages\\traitlets\\config\\application.py\", line 846, in launch_instance\n",
      "    app.start()\n",
      "  File \"C:\\Users\\point\\anaconda3\\lib\\site-packages\\ipykernel\\kernelapp.py\", line 677, in start\n",
      "    self.io_loop.start()\n",
      "  File \"C:\\Users\\point\\anaconda3\\lib\\site-packages\\tornado\\platform\\asyncio.py\", line 199, in start\n",
      "    self.asyncio_loop.run_forever()\n",
      "  File \"C:\\Users\\point\\anaconda3\\lib\\asyncio\\base_events.py\", line 596, in run_forever\n",
      "    self._run_once()\n",
      "  File \"C:\\Users\\point\\anaconda3\\lib\\asyncio\\base_events.py\", line 1890, in _run_once\n",
      "    handle._run()\n",
      "  File \"C:\\Users\\point\\anaconda3\\lib\\asyncio\\events.py\", line 94, in _run\n",
      "    self._loop.call_exception_handler(context)\n",
      "  File \"C:\\Users\\point\\anaconda3\\lib\\asyncio\\base_events.py\", line 1771, in call_exception_handler\n",
      "    logger.error('Exception in default exception handler',\n",
      "  File \"C:\\Users\\point\\anaconda3\\lib\\logging\\__init__.py\", line 1475, in error\n",
      "    self._log(ERROR, msg, args, **kwargs)\n",
      "  File \"C:\\Users\\point\\anaconda3\\lib\\logging\\__init__.py\", line 1589, in _log\n",
      "    self.handle(record)\n",
      "  File \"C:\\Users\\point\\anaconda3\\lib\\logging\\__init__.py\", line 1599, in handle\n",
      "    self.callHandlers(record)\n",
      "  File \"C:\\Users\\point\\anaconda3\\lib\\logging\\__init__.py\", line 1661, in callHandlers\n",
      "    hdlr.handle(record)\n",
      "  File \"C:\\Users\\point\\anaconda3\\lib\\logging\\__init__.py\", line 952, in handle\n",
      "    self.emit(record)\n",
      "  File \"C:\\Users\\point\\anaconda3\\lib\\logging\\__init__.py\", line 1091, in emit\n",
      "    self.handleError(record)\n",
      "  File \"C:\\Users\\point\\anaconda3\\lib\\logging\\__init__.py\", line 1005, in handleError\n",
      "    traceback.print_exception(t, v, tb, None, sys.stderr)\n",
      "  File \"C:\\Users\\point\\anaconda3\\lib\\traceback.py\", line 103, in print_exception\n",
      "    for line in TracebackException(\n",
      "  File \"C:\\Users\\point\\anaconda3\\lib\\traceback.py\", line 533, in __init__\n",
      "    self._load_lines()\n",
      "  File \"C:\\Users\\point\\anaconda3\\lib\\traceback.py\", line 545, in _load_lines\n",
      "    self.__context__._load_lines()\n",
      "  File \"C:\\Users\\point\\anaconda3\\lib\\traceback.py\", line 545, in _load_lines\n",
      "    self.__context__._load_lines()\n",
      "  File \"C:\\Users\\point\\anaconda3\\lib\\traceback.py\", line 545, in _load_lines\n",
      "    self.__context__._load_lines()\n",
      "  [Previous line repeated 12 more times]\n",
      "  File \"C:\\Users\\point\\anaconda3\\lib\\traceback.py\", line 543, in _load_lines\n",
      "    frame.line\n",
      "  File \"C:\\Users\\point\\anaconda3\\lib\\traceback.py\", line 288, in line\n",
      "    self._line = linecache.getline(self.filename, self.lineno).strip()\n",
      "  File \"C:\\Users\\point\\anaconda3\\lib\\linecache.py\", line 30, in getline\n",
      "    lines = getlines(filename, module_globals)\n",
      "  File \"C:\\Users\\point\\anaconda3\\lib\\linecache.py\", line 46, in getlines\n",
      "    return updatecache(filename, module_globals)\n",
      "  File \"C:\\Users\\point\\anaconda3\\lib\\linecache.py\", line 137, in updatecache\n",
      "    lines = fp.readlines()\n",
      "  File \"C:\\Users\\point\\anaconda3\\lib\\codecs.py\", line 322, in decode\n",
      "    (result, consumed) = self._buffer_decode(data, self.errors, final)\n",
      "UnicodeDecodeError: 'utf-8' codec can't decode byte 0xb0 in position 2726: invalid start byte\n"
     ]
    },
    {
     "ename": "Error",
     "evalue": "Canceled future for execute_request message before replies were done",
     "output_type": "error",
     "traceback": [
      "Error: Canceled future for execute_request message before replies were done",
      "at t.KernelShellFutureHandler.dispose (c:\\Users\\point\\.vscode\\extensions\\ms-toolsai.jupyter-2022.3.1000901801\\out\\extension.js:2:1204175)",
      "at c:\\Users\\point\\.vscode\\extensions\\ms-toolsai.jupyter-2022.3.1000901801\\out\\extension.js:2:1223227",
      "at Map.forEach (<anonymous>)",
      "at v._clearKernelState (c:\\Users\\point\\.vscode\\extensions\\ms-toolsai.jupyter-2022.3.1000901801\\out\\extension.js:2:1223212)",
      "at v.dispose (c:\\Users\\point\\.vscode\\extensions\\ms-toolsai.jupyter-2022.3.1000901801\\out\\extension.js:2:1216694)",
      "at c:\\Users\\point\\.vscode\\extensions\\ms-toolsai.jupyter-2022.3.1000901801\\out\\extension.js:2:533674",
      "at t.swallowExceptions (c:\\Users\\point\\.vscode\\extensions\\ms-toolsai.jupyter-2022.3.1000901801\\out\\extension.js:2:913059)",
      "at dispose (c:\\Users\\point\\.vscode\\extensions\\ms-toolsai.jupyter-2022.3.1000901801\\out\\extension.js:2:533652)",
      "at t.RawSession.dispose (c:\\Users\\point\\.vscode\\extensions\\ms-toolsai.jupyter-2022.3.1000901801\\out\\extension.js:2:537330)",
      "at runMicrotasks (<anonymous>)",
      "at processTicksAndRejections (node:internal/process/task_queues:96:5)"
     ]
    }
   ],
   "source": [
    "d2 = Deque()\n",
    "\n",
    "print(d2)\n",
    "\n",
    "d2.add_first(\"1\")\n",
    "print(d2)\n",
    "d2.add_first(\"2\")\n",
    "print(d2)\n",
    "d2.add_first(\"3\")\n",
    "print(d2)\n",
    "\n",
    "d2.add_last(\"10\")\n",
    "print(d2)\n",
    "d2.add_last(\"20\")\n",
    "print(d2)\n",
    "d2.add_last(\"30\")\n",
    "print(d2)\n",
    "d2.add_last(\"40\")\n",
    "print(d2)\n",
    "\n",
    "print(d2.delete_first())\n",
    "print(d2)\n",
    "print(d2.delete_first())\n",
    "print(d2)\n",
    "print(d2.delete_first())\n",
    "print(d2)\n",
    "print(d2.delete_first())\n",
    "print(d2)\n",
    "print(d2.delete_first())\n",
    "print(d2)\n",
    "\n",
    "d2.add_last(\"50\")\n",
    "print(d2)\n",
    "d2.add_last(\"60\")\n",
    "print(d2)\n",
    "\n",
    "# print(d2.delete_last())\n",
    "# print(d2)\n",
    "# print(d2.delete_last())\n",
    "# print(d2)"
   ]
  }
 ],
 "metadata": {
  "kernelspec": {
   "display_name": "Python 3 (ipykernel)",
   "language": "python",
   "name": "python3"
  },
  "language_info": {
   "codemirror_mode": {
    "name": "ipython",
    "version": 3
   },
   "file_extension": ".py",
   "mimetype": "text/x-python",
   "name": "python",
   "nbconvert_exporter": "python",
   "pygments_lexer": "ipython3",
   "version": "3.9.7"
  }
 },
 "nbformat": 4,
 "nbformat_minor": 5
}
